2021-02-16 01:14:17.019759: W tensorflow/stream_executor/platform/default/dso_loader.cc:59] Could not load dynamic library 'libcudart.so.10.1'; dlerror: libcudart.so.10.1: cannot open shared object file: No such file or directory; LD_LIBRARY_PATH: /home/software/python/3.8.3/lib:/home/software/sqlite3/3.22.0/lib:/home/software/sloan/local/lib:/home/software/gcc/6.2.0/lib64:/home/software/gcc/6.2.0/lib
2021-02-16 01:14:17.019800: I tensorflow/stream_executor/cuda/cudart_stub.cc:29] Ignore above cudart dlerror if you do not have a GPU set up on your machine.
2021-02-16 01:14:23.751512: W tensorflow/stream_executor/platform/default/dso_loader.cc:59] Could not load dynamic library 'libcuda.so.1'; dlerror: libcuda.so.1: cannot open shared object file: No such file or directory; LD_LIBRARY_PATH: /home/software/python/3.8.3/lib:/home/software/sqlite3/3.22.0/lib:/home/software/sloan/local/lib:/home/software/gcc/6.2.0/lib64:/home/software/gcc/6.2.0/lib
2021-02-16 01:14:23.751560: W tensorflow/stream_executor/cuda/cuda_driver.cc:312] failed call to cuInit: UNKNOWN ERROR (303)
2021-02-16 01:14:23.751592: I tensorflow/stream_executor/cuda/cuda_diagnostics.cc:156] kernel driver does not appear to be running on this host (node439.cm.cluster): /proc/driver/nvidia/version does not exist
2021-02-16 01:14:23.752089: I tensorflow/core/platform/cpu_feature_guard.cc:142] This TensorFlow binary is optimized with oneAPI Deep Neural Network Library (oneDNN)to use the following CPU instructions in performance-critical operations:  AVX2 FMA
To enable them in other operations, rebuild TensorFlow with the appropriate compiler flags.
2021-02-16 01:14:23.766797: I tensorflow/core/platform/profile_utils/cpu_utils.cc:104] CPU Frequency: 2000144999 Hz
2021-02-16 01:14:23.767651: I tensorflow/compiler/xla/service/service.cc:168] XLA service 0x9a0d9d0 initialized for platform Host (this does not guarantee that XLA will be used). Devices:
2021-02-16 01:14:23.767682: I tensorflow/compiler/xla/service/service.cc:176]   StreamExecutor device (0): Host, Default Version
Using TensorFlow backend.
Traceback (most recent call last):
  File "./main_train.py", line 128, in <module>
    knn.fit(df_train, regions_train)
  File "/nfs/sloanlab003/projects/covid_t2_proj/covid19_team2_wf/covid19_team2/codes/knn_model.py", line 76, in fit
    self.state_df = self.state_df[['state', 'date', 'cases', 'deaths', 'temperature', 'PRCP_median_scaled']]
  File "/home/nzendong/.local/lib/python3.8/site-packages/pandas/core/frame.py", line 2912, in __getitem__
    indexer = self.loc._get_listlike_indexer(key, axis=1, raise_missing=True)[1]
  File "/home/nzendong/.local/lib/python3.8/site-packages/pandas/core/indexing.py", line 1254, in _get_listlike_indexer
    self._validate_read_indexer(keyarr, indexer, axis, raise_missing=raise_missing)
  File "/home/nzendong/.local/lib/python3.8/site-packages/pandas/core/indexing.py", line 1304, in _validate_read_indexer
    raise KeyError(f"{not_found} not in index")
KeyError: "['PRCP_median_scaled'] not in index"
